<?xml version="1.0" encoding="utf-8"?>
<!-- This URDF was automatically created by SolidWorks to URDF Exporter! Originally created by Stephen Brawner (brawner@gmail.com) 
     Commit Version: 1.6.0-4-g7f85cfe  Build Version: 1.6.7995.38578
     For more information, please see http://wiki.ros.org/sw_urdf_exporter -->
<robot name="yahboomcar_M1" xmlns:xacro="http://ros.org/wiki/xacro">
  <link name="imu_link"/>
  <link
    name="base_link">
    <inertial>
      <origin
        xyz="-0.00147894878595477 -7.65058525461934E-05 0.0372156593091129"
        rpy="0 0 0" />
      <mass
        value="1.11636914474168" />
      <inertia
        ixx="0.0018277057054687"
        ixy="-2.42363637378439E-06"
        ixz="6.10477724665455E-05"
        iyy="0.00349135899627017"
        iyz="1.85575405511059E-07"
        izz="0.00473244016900535" />
    </inertial>
    <visual>
      <origin
        xyz="0 0 0"
        rpy="0 0 0" />
      <geometry>
        <mesh
          filename="package://yahboomcar_description/meshes/M1USBMecanum/base_link.STL" />
      </geometry>
      <material
        name="">
        <color
          rgba="0.898039215686275 0.917647058823529 0.929411764705882 1" />
      </material>
    </visual>
    <collision>
      <origin
        xyz="0 0 0"
        rpy="0 0 0" />
      <geometry>
        <mesh
          filename="package://yahboomcar_description/meshes/M1USBMecanum/base_link.STL" />
      </geometry>
    </collision>
  </link>
  <link
    name="le_fr_Link">
    <inertial>
      <origin
        xyz="3.74167867880498E-05 0.0119013763465429 1.86340826510943E-05"
        rpy="0 0 0" />
      <mass
        value="0.10186824351" />
      <inertia
        ixx="4.56509059603618E-05"
        ixy="1.72108152415771E-09"
        ixz="1.03245732008585E-10"
        iyy="7.54636523798736E-05"
        iyz="-2.41200561433929E-09"
        izz="4.56518356202479E-05" />
    </inertial>
    <visual>
      <origin
        xyz="0 0 0"
        rpy="0 0 0" />
      <geometry>
        <mesh
          filename="package://yahboomcar_description/meshes/M1USBMecanum/le_fr_Link.STL" />
      </geometry>
      <material
        name="">
        <color
          rgba="0.298039215686275 0.298039215686275 0.298039215686275 1" />
      </material>
    </visual>
    <collision>
      <origin
        xyz="0 0 0"
        rpy="0 0 0" />
      <geometry>
        <mesh
          filename="package://yahboomcar_description/meshes/M1USBMecanum/le_fr_Link.STL" />
      </geometry>
    </collision>
  </link>
  <joint
    name="le_fr"
    type="continuous">
    <origin
      xyz="0.092963 0.08475 0.012478"
      rpy="0 0 0" />
    <parent
      link="base_link" />
    <child
      link="le_fr_Link" />
    <axis
      xyz="0 1 0" />
    <limit
      effort="0"
      velocity="1000" />
  </joint>
  <link
    name="le_be_Link">
    <inertial>
      <origin
        xyz="2.11977386245787E-05 0.0119013486320377 -1.06209102313203E-05"
        rpy="0 0 0" />
      <mass
        value="0.101866167391129" />
      <inertia
        ixx="4.56501476687068E-05"
        ixy="1.61518953792119E-09"
        ixz="-1.7365376438756E-10"
        iyy="7.54628872801991E-05"
        iyz="1.61143253760027E-09"
        izz="4.56509848428076E-05" />
    </inertial>
    <visual>
      <origin
        xyz="0 0 0"
        rpy="0 0 0" />
      <geometry>
        <mesh
          filename="package://yahboomcar_description/meshes/M1USBMecanum/le_be_Link.STL" />
      </geometry>
      <material
        name="">
        <color
          rgba="0.298039215686275 0.298039215686275 0.298039215686275 1" />
      </material>
    </visual>
    <collision>
      <origin
        xyz="0 0 0"
        rpy="0 0 0" />
      <geometry>
        <mesh
          filename="package://yahboomcar_description/meshes/M1USBMecanum/le_be_Link.STL" />
      </geometry>
    </collision>
  </link>
  <joint
    name="le_be"
    type="continuous">
    <origin
      xyz="-0.093021 0.08475 0.012513"
      rpy="0 0 0" />
    <parent
      link="base_link" />
    <child
      link="le_be_Link" />
    <axis
      xyz="0 1 0" />
    <limit
      effort="0"
      velocity="1000" />
  </joint>
  <link
    name="ri_fr_Link">
    <inertial>
      <origin
        xyz="2.11975932214864E-05 -0.0119013488213277 9.31997418530429E-06"
        rpy="0 0 0" />
      <mass
        value="0.101866166607628" />
      <inertia
        ixx="4.56501477319824E-05"
        ixy="-1.61489968094019E-09"
        ixz="1.73527476659117E-10"
        iyy="7.54628872430994E-05"
        iyz="2.46884367239952E-09"
        izz="4.56509846351022E-05" />
    </inertial>
    <visual>
      <origin
        xyz="0 0 0"
        rpy="0 0 0" />
      <geometry>
        <mesh
          filename="package://yahboomcar_description/meshes/M1USBMecanum/ri_fr_Link.STL" />
      </geometry>
      <material
        name="">
        <color
          rgba="0.298039215686275 0.298039215686275 0.298039215686275 1" />
      </material>
    </visual>
    <collision>
      <origin
        xyz="0 0 0"
        rpy="0 0 0" />
      <geometry>
        <mesh
          filename="package://yahboomcar_description/meshes/M1USBMecanum/ri_fr_Link.STL" />
      </geometry>
    </collision>
  </link>
  <joint
    name="ri_fr"
    type="continuous">
    <origin
      xyz="0.092979 -0.08475 0.012487"
      rpy="0 0 0" />
    <parent
      link="base_link" />
    <child
      link="ri_fr_Link" />
    <axis
      xyz="0 1 0" />
    <limit
      effort="0"
      velocity="1000" />
  </joint>
  <link
    name="ri_be_Link">
    <inertial>
      <origin
        xyz="-3.74168655802587E-05 -0.0119013767684317 1.86342357507731E-05"
        rpy="0 0 0" />
      <mass
        value="0.101868242572479" />
      <inertia
        ixx="4.56509056936808E-05"
        ixy="1.72132416722607E-09"
        ixz="-1.03742122959087E-10"
        iyy="7.54636518678042E-05"
        iyz="2.41227507293991E-09"
        izz="4.56518347566621E-05" />
    </inertial>
    <visual>
      <origin
        xyz="0 0 0"
        rpy="0 0 0" />
      <geometry>
        <mesh
          filename="package://yahboomcar_description/meshes/M1USBMecanum/ri_be_Link.STL" />
      </geometry>
      <material
        name="">
        <color
          rgba="0.298039215686275 0.298039215686275 0.298039215686275 1" />
      </material>
    </visual>
    <collision>
      <origin
        xyz="0 0 0"
        rpy="0 0 0" />
      <geometry>
        <mesh
          filename="package://yahboomcar_description/meshes/M1USBMecanum/ri_be_Link.STL" />
      </geometry>
    </collision>
  </link>
  <joint
    name="ri_be"
    type="continuous">
    <origin
      xyz="-0.092963 -0.08475 0.012478"
      rpy="0 0 0" />
    <parent
      link="base_link" />
    <child
      link="ri_be_Link" />
    <axis
      xyz="0 1 0" />
    <limit
      effort="0"
      velocity="1000" />
  </joint>
  <link
    name="cam1_Link">
    <inertial>
      <origin
        xyz="0.0118309104400736 -0.00345038635158399 0.0180767104721753"
        rpy="0 0 0" />
      <mass
        value="0.00991850362270258" />
      <inertia
        ixx="1.630567342831E-06"
        ixy="-1.44952065784027E-09"
        ixz="-2.68839729159241E-07"
        iyy="9.59559665974569E-07"
        iyz="8.7282110277673E-09"
        izz="1.37354571417538E-06" />
    </inertial>
    <visual>
      <origin
        xyz="0 0 0"
        rpy="0 0 0" />
      <geometry>
        <mesh
          filename="package://yahboomcar_description/meshes/M1USBMecanum/cam1_Link.STL" />
      </geometry>
      <material
        name="">
        <color
          rgba="1 1 1 1" />
      </material>
    </visual>
    <collision>
      <origin
        xyz="0 0 0"
        rpy="0 0 0" />
      <geometry>
        <mesh
          filename="package://yahboomcar_description/meshes/M1USBMecanum/cam1_Link.STL" />
      </geometry>
    </collision>
  </link>
  <joint
    name="cam1"
    type="revolute">
    <origin
      xyz="0.095521 0.0001 0.084136"
      rpy="0 0 0" />
    <parent
      link="base_link" />
    <child
      link="cam1_Link" />
    <axis
      xyz="0 0 1" />
    <limit
      lower="-1.5708"
      upper="1.5708"
      effort="0"
      velocity="0" />
  </joint>
  <link
    name="cam2_Link">
    <inertial>
      <origin
        xyz="0.000145138667098364 0.0046164557014842 0.0147109977799166"
        rpy="0 0 0" />
      <mass
        value="0.00952096614624627" />
      <inertia
        ixx="1.66615942686859E-06"
        ixy="-3.29093619596985E-10"
        ixz="-4.17461760561191E-09"
        iyy="2.26284036783286E-06"
        iyz="2.79109955725232E-07"
        izz="2.31308353566235E-06" />
    </inertial>
    <visual>
      <origin
        xyz="0 0 0"
        rpy="0 0 0" />
      <geometry>
        <mesh
          filename="package://yahboomcar_description/meshes/M1USBMecanum/cam2_Link.STL" />
      </geometry>
      <material
        name="">
        <color
          rgba="0.298039215686275 0.298039215686275 0.298039215686275 1" />
      </material>
    </visual>
    <collision>
      <origin
        xyz="0 0 0"
        rpy="0 0 0" />
      <geometry>
        <mesh
          filename="package://yahboomcar_description/meshes/M1USBMecanum/cam2_Link.STL" />
      </geometry>
    </collision>
  </link>
  <joint
    name="cam2"
    type="revolute">
    <origin
      xyz="0.016875 0.00062107 0.025108"
      rpy="1.5708 0 1.5708" />
    <parent
      link="cam1_Link" />
    <child
      link="cam2_Link" />
    <axis
      xyz="1 0 0" />
    <limit
      lower="-0.7854"
      upper="0.5236"
      effort="0"
      velocity="0" />
  </joint>
  <link
    name="laser_Link">
    <inertial>
      <origin
        xyz="-0.00032594808079998 -9.29243200874192E-05 -0.0167019587624581"
        rpy="0 0 0" />
      <mass
        value="0.0328500127662789" />
      <inertia
        ixx="1.08456634708925E-05"
        ixy="-2.4161667733829E-09"
        ixz="1.62792126980607E-08"
        iyy="1.07910219759566E-05"
        iyz="-4.20268040515039E-09"
        izz="1.96412189369573E-05" />
    </inertial>
    <visual>
      <origin
        xyz="0 0 0"
        rpy="0 0 0" />
      <geometry>
        <mesh
          filename="package://yahboomcar_description/meshes/M1USBMecanum/laser_Link.STL" />
      </geometry>
      <material
        name="">
        <color
          rgba="0.298039215686275 0.298039215686275 0.298039215686275 1" />
      </material>
    </visual>
    <collision>
      <origin
        xyz="0 0 0"
        rpy="0 0 0" />
      <geometry>
        <mesh
          filename="package://yahboomcar_description/meshes/M1USBMecanum/laser_Link.STL" />
      </geometry>
    </collision>
  </link>
  <joint
    name="laser"
    type="fixed">
    <origin
      xyz="0.010059 0 0.15058"
      rpy="0 0 0" />
    <parent
      link="base_link" />
    <child
      link="laser_Link" />
    <axis
      xyz="0 0 0" />
    <limit
      effort="0"
      velocity="1000" />
  </joint>
  <joint name="base_imu" type="fixed">
  <parent link="base_link"/>
  <child link="imu_link"/>
  <origin xyz="-0.025 -0.034 -0.0165" rpy="0 0 0"/>
  </joint>

  <link name="base_footprint"/>
  <joint name="base_joint" type="fixed">
    <parent link="base_footprint"/>
    <child link="base_link"/>
    <origin xyz="0.0 0.0 0.0215" rpy="0 0 0"/>
  </joint>
</robot>